<?xml version="1.0" ?>
<!-- =================================================================================== -->
<!-- |    This document was autogenerated by xacro from scout_asm.urdf                 | -->
<!-- |    EDITING THIS FILE BY HAND IS NOT RECOMMENDED                                 | -->
<!-- =================================================================================== -->
<!-- This URDF was automatically created by SolidWorks to URDF Exporter! Originally created by Stephen Brawner (brawner@gmail.com) 
     Commit Version: 1.6.0-4-g7f85cfe  Build Version: 1.6.7995.38578
     For more information, please see http://wiki.ros.org/sw_urdf_exporter -->
<robot name="scout_asm">
  <link name="base_link">
    <inertial>
      <origin rpy="0 0 0" xyz="-0.000886842902329518 0.000253112961531232 0.0309916867214636"/>
      <mass value="71.248451235273"/>
      <inertia ixx="6.75685705276497" ixy="-0.00399954038625876" ixz="-0.264710072044026" iyy="8.11766845319496" iyz="-0.000278279991055837" izz="6.59432020448618"/>
    </inertial>
    <visual>
      <origin rpy="0 0 0" xyz="0 0 0"/>
      <geometry>
        <mesh filename="package://scout_asm/meshes/base_link.STL"/>
      </geometry>
      <material name="">
        <color rgba="0.792156862745098 0.819607843137255 0.933333333333333 1"/>
      </material>
    </visual>
    <collision>
      <origin rpy="0 0 0" xyz="0 0 0"/>
      <geometry>
        <mesh filename="package://scout_asm/meshes/base_link.STL"/>
      </geometry>
    </collision>
  </link>
  <link name="back_right_wheel_link">
    <inertial>
      <origin rpy="0 0 0" xyz="1.98217269052059E-05 0.000311966682915443 -4.14769423991851E-06"/>
      <mass value="6.27512049321104"/>
      <inertia ixx="0.048710557605628" ixy="-3.22920684861355E-07" ixz="-4.24672173216801E-06" iyy="0.0871019043950529" iyz="4.92925505186038E-08" izz="0.0486921980597497"/>
    </inertial>
    <visual>
      <origin rpy="0 0 0" xyz="0 0 0"/>
      <geometry>
        <mesh filename="package://scout_asm/meshes/back_right_wheel_link.STL"/>
      </geometry>
      <material name="">
        <color rgba="1 1 1 1"/>
      </material>
    </visual>
    <collision>
      <origin rpy="0 0 0" xyz="0 0 0"/>
      <geometry>
        <mesh filename="package://scout_asm/meshes/back_right_wheel_link.STL"/>
      </geometry>
    </collision>
  </link>
  <joint name="back_right_wheel_joint" type="continuous">
    <origin rpy="3.1416 0 0" xyz="-0.252 -0.29153 -0.088205"/>
    <parent link="base_link"/>
    <child link="back_right_wheel_link"/>
    <axis xyz="0 -1 0"/>
  </joint>
  <link name="front_right_wheel_link">
    <inertial>
      <origin rpy="0 0 0" xyz="1.95085710585352E-05 0.000311941884546418 5.43206872193058E-06"/>
      <mass value="6.27512070641512"/>
      <inertia ixx="0.048710152416571" ixy="-3.09427341489682E-07" ixz="5.02956834271363E-06" iyy="0.0871018747298875" iyz="-1.04724151382019E-07" izz="0.0486925857241658"/>
    </inertial>
    <visual>
      <origin rpy="0 0 0" xyz="0 0 0"/>
      <geometry>
        <mesh filename="package://scout_asm/meshes/front_right_wheel_link.STL"/>
      </geometry>
      <material name="">
        <color rgba="1 1 1 1"/>
      </material>
    </visual>
    <collision>
      <origin rpy="0 0 0" xyz="0 0 0"/>
      <geometry>
        <mesh filename="package://scout_asm/meshes/front_right_wheel_link.STL"/>
      </geometry>
    </collision>
  </link>
  <joint name="front_right_wheel_joint" type="continuous">
    <origin rpy="3.1416 0 0" xyz="0.252 -0.29153 -0.088205"/>
    <parent link="base_link"/>
    <child link="front_right_wheel_link"/>
    <axis xyz="0 -1 0"/>
  </joint>
  <link name="front_left_wheel_link">
    <inertial>
      <origin rpy="0 0 0" xyz="1.65883236641351E-05 0.00331195632306674 -1.16159711724059E-05"/>
      <mass value="6.2751208349232"/>
      <inertia ixx="0.048704659740351" ixy="-2.77438236234826E-07" ixz="-9.59133113568662E-06" iyy="0.0871018893060342" iyz="1.72438046561457E-07" izz="0.0486980869080159"/>
    </inertial>
    <visual>
      <origin rpy="0 0 0" xyz="0 0 0"/>
      <geometry>
        <mesh filename="package://scout_asm/meshes/front_left_wheel_link.STL"/>
      </geometry>
      <material name="">
        <color rgba="1 1 1 1"/>
      </material>
    </visual>
    <collision>
      <origin rpy="0 0 0" xyz="0 0 0"/>
      <geometry>
        <mesh filename="package://scout_asm/meshes/front_left_wheel_link.STL"/>
      </geometry>
    </collision>
  </link>
  <joint name="front_left_wheel_joint" type="continuous">
    <origin rpy="-3.1416 0 3.1416" xyz="0.252 0.29153 -0.088205"/>
    <parent link="base_link"/>
    <child link="front_left_wheel_link"/>
    <axis xyz="0 -1 0"/>
  </joint>
  <link name="back_left_wheel_link">
    <inertial>
      <origin rpy="0 0 0" xyz="2.01463918039213E-05 0.000311954587836172 2.03779970718229E-06"/>
      <mass value="6.27512066932487"/>
      <inertia ixx="0.0487113172312305" ixy="-3.23083126301365E-07" ixz="1.82709216823691E-06" iyy="0.0871018747128032" iyz="-5.05179516426061E-08" izz="0.0486914208744096"/>
    </inertial>
    <visual>
      <origin rpy="0 0 0" xyz="0 0 0"/>
      <geometry>
        <mesh filename="package://scout_asm/meshes/back_left_wheel_link.STL"/>
      </geometry>
      <material name="">
        <color rgba="1 1 1 1"/>
      </material>
    </visual>
    <collision>
      <origin rpy="0 0 0" xyz="0 0 0"/>
      <geometry>
        <mesh filename="package://scout_asm/meshes/back_left_wheel_link.STL"/>
      </geometry>
    </collision>
  </link>
  <joint name="back_left_wheel_joint" type="continuous">
    <origin rpy="-3.1416 0 3.1416" xyz="-0.252 0.29153 -0.088205"/>
    <parent link="base_link"/>
    <child link="back_left_wheel_link"/>
    <axis xyz="0 -1 0"/>
  </joint>
  <link name="IMU_link">
    <inertial>
      <origin rpy="0 0 0" xyz="-0.0497381570976722 -0.000503112961527634 -0.493508313278529"/>
      <mass value="71.248451235273"/>
      <inertia ixx="6.75685705276497" ixy="-0.00399954038625873" ixz="0.264710072044025" iyy="8.11766845319496" iyz="0.000278279991055734" izz="6.59432020448618"/>
    </inertial>
    <visual>
      <origin rpy="0 0 0" xyz="0 0 0"/>
      <geometry>
        <mesh filename="package://scout_asm/meshes/IMU_link.STL"/>
      </geometry>
      <material name="">
        <color rgba="0.792156862745098 0.819607843137255 0.933333333333333 1"/>
      </material>
    </visual>
    <collision>
      <origin rpy="0 0 0" xyz="0 0 0"/>
      <geometry>
        <mesh filename="package://scout_asm/meshes/IMU_link.STL"/>
      </geometry>
    </collision>
  </link>
  <joint name="IMU_joint" type="fixed">
    <origin rpy="0 0 3.1416" xyz="-0.050625 -0.00025 0.5245"/>
    <parent link="base_link"/>
    <child link="IMU_link"/>
    <axis xyz="0 0 0"/>
  </joint>
  <link name="GPS_link">
    <inertial>
      <origin rpy="0 0 0" xyz="-0.0751368429023226 0.000253112961518601 -1.02650831327853"/>
      <mass value="71.248451235273"/>
      <inertia ixx="6.75685705276497" ixy="-0.00399954038625875" ixz="-0.264710072044025" iyy="8.11766845319496" iyz="-0.00027827999105583" izz="6.59432020448618"/>
    </inertial>
    <visual>
      <origin rpy="0 0 0" xyz="0 0 0"/>
      <geometry>
        <mesh filename="package://scout_asm/meshes/GPS_link.STL"/>
      </geometry>
      <material name="">
        <color rgba="0.792156862745098 0.819607843137255 0.933333333333333 1"/>
      </material>
    </visual>
    <collision>
      <origin rpy="0 0 0" xyz="0 0 0"/>
      <geometry>
        <mesh filename="package://scout_asm/meshes/GPS_link.STL"/>
      </geometry>
    </collision>
  </link>
  <joint name="GPS_joint" type="fixed">
    <origin rpy="0 0 0" xyz="0.07425 0 1.0575"/>
    <parent link="base_link"/>
    <child link="GPS_link"/>
    <axis xyz="0 0 0"/>
  </joint>
  <link name="camera_link">
    <inertial>
      <origin rpy="0 0 0" xyz="-9.15128339706842E-07 0.000181095000216125 -0.0192686525777699"/>
      <mass value="0.170322733622974"/>
      <inertia ixx="3.25740332390363E-05" ixy="1.36456425941007E-09" ixz="-3.30060648014934E-09" iyy="0.000390616603989006" iyz="6.45404483704483E-08" izz="0.000382942750152863"/>
    </inertial>
    <visual>
      <origin rpy="0 0 0" xyz="0 0 0"/>
      <geometry>
        <mesh filename="package://scout_asm/meshes/camera_link.STL"/>
      </geometry>
      <material name="">
        <color rgba="0.792156862745098 0.819607843137255 0.933333333333333 1"/>
      </material>
    </visual>
    <collision>
      <origin rpy="0 0 0" xyz="0 0 0"/>
      <geometry>
        <mesh filename="package://scout_asm/meshes/camera_link.STL"/>
      </geometry>
    </collision>
  </link>
  <joint name="camera_joint" type="fixed">
    <origin rpy="-1.8876 0 -1.5708" xyz="0.40627 0 0.8138"/>
    <parent link="base_link"/>
    <child link="camera_link"/>
    <axis xyz="0 0 0"/>
  </joint>
  <link name="Lidar_link">
    <inertial>
      <origin rpy="0 0 0" xyz="2.58702285259392E-06 -7.51320216247353E-05 -0.00186827723650795"/>
      <mass value="0.583537708098001"/>
      <inertia ixx="0.000629514111361371" ixy="-1.12600646657801E-10" ixz="5.00502875846714E-08" iyy="0.000629061975553881" iyz="6.84879643022102E-08" izz="0.000748501972377939"/>
    </inertial>
    <visual>
      <origin rpy="0 0 0" xyz="0 0 0"/>
      <geometry>
        <mesh filename="package://scout_asm/meshes/Lidar_link.STL"/>
      </geometry>
      <material name="">
        <color rgba="0.905882352941176 0.992156862745098 1 0.4"/>
      </material>
    </visual>
    <collision>
      <origin rpy="0 0 0" xyz="0 0 0"/>
      <geometry>
        <mesh filename="package://scout_asm/meshes/Lidar_link.STL"/>
      </geometry>
    </collision>
  </link>
  <joint name="Lidar_joint" type="fixed">
    <origin rpy="0 0 -1.5708" xyz="0.28025 0.0005 1.1457"/>
    <parent link="base_link"/>
    <child link="Lidar_link"/>
    <axis xyz="0 0 0"/>
  </joint>
  <link name="Profile_link">
    <inertial>
      <origin rpy="0 0 0" xyz="-0.0891131570976722 -0.000253112961527518 -0.474008313278529"/>
      <mass value="71.248451235273"/>
      <inertia ixx="6.75685705276497" ixy="-0.00399954038625873" ixz="0.264710072044025" iyy="8.11766845319496" iyz="0.000278279991055665" izz="6.59432020448618"/>
    </inertial>
    <visual>
      <origin rpy="0 0 0" xyz="0 0 0"/>
      <geometry>
        <mesh filename="package://scout_asm/meshes/Profile_link.STL"/>
      </geometry>
      <material name="">
        <color rgba="0.792156862745098 0.819607843137255 0.933333333333333 1"/>
      </material>
    </visual>
    <collision>
      <origin rpy="0 0 0" xyz="0 0 0"/>
      <geometry>
        <mesh filename="package://scout_asm/meshes/Profile_link.STL"/>
      </geometry>
    </collision>
  </link>
  
  <joint name="Profile_joint" type="fixed">
    <origin rpy="0 0 3.1416" xyz="-0.09 0 0.505"/>
    <parent link="base_link"/>
    <child link="Profile_link"/>
    <axis xyz="0 0 0"/>
  </joint>
</robot>

